Workbook

Sheet Resumen
A1: Resumen de costos - Plataforma de Atención de Enfermería Medical Health
A2: Comparación mensual por categoría en pesos colombianos (COP), pago por uso. Precios de lista en USD consultados en Octubre 2026 y convertidos con la TRM de la hoja Supuestos.
A4: Categoría | B4: Azure (COP/mes) | C4: AWS (COP/mes) | D4: Diferencia (Azure - AWS) | E4: % Azure sobre total | F4: Azure (COP/año) | G4: AWS (COP/año)
A5: Computación | B5: =SUMIF(Azure!$A$4:$A$53,$A5,Azure!$J$4:$J$53) | C5: =SUMIF(AWS!$A$4:$A$55,$A5,AWS!$J$4:$J$55) | D5: =B5-C5 | E5: =B5/$B$12 | F5: =B5*12 | G5: =C5*12
A6: Almacenamiento y Bases de Datos | B6: =SUMIF(Azure!$A$4:$A$53,$A6,Azure!$J$4:$J$53) | C6: =SUMIF(AWS!$A$4:$A$55,$A6,AWS!$J$4:$J$55) | D6: =B6-C6 | E6: =B6/$B$12 | F6: =B6*12 | G6: =C6*12
A7: Redes | B7: =SUMIF(Azure!$A$4:$A$53,$A7,Azure!$J$4:$J$53) | C7: =SUMIF(AWS!$A$4:$A$55,$A7,AWS!$J$4:$J$55) | D7: =B7-C7 | E7: =B7/$B$12 | F7: =B7*12 | G7: =C7*12
A8: Seguridad | B8: =SUMIF(Azure!$A$4:$A$53,$A8,Azure!$J$4:$J$53) | C8: =SUMIF(AWS!$A$4:$A$55,$A8,AWS!$J$4:$J$55) | D8: =B8-C8 | E8: =B8/$B$12 | F8: =B8*12 | G8: =C8*12
A9: Monitoreo y Logs | B9: =SUMIF(Azure!$A$4:$A$53,$A9,Azure!$J$4:$J$53) | C9: =SUMIF(AWS!$A$4:$A$55,$A9,AWS!$J$4:$J$55) | D9: =B9-C9 | E9: =B9/$B$12 | F9: =B9*12 | G9: =C9*12
A10: Servicios de Plataforma | B10: =SUMIF(Azure!$A$4:$A$53,$A10,Azure!$J$4:$J$53) | C10: =SUMIF(AWS!$A$4:$A$55,$A10,AWS!$J$4:$J$55) | D10: =B10-C10 | E10: =B10/$B$12 | F10: =B10*12 | G10: =C10*12
A11: Ambiente Dev/Test | B11: =SUMIF(Azure!$A$4:$A$53,$A11,Azure!$J$4:$J$53) | C11: =SUMIF(AWS!$A$4:$A$55,$A11,AWS!$J$4:$J$55) | D11: =B11-C11 | E11: =B11/$B$12 | F11: =B11*12 | G11: =C11*12
A12: TOTAL | B12: =SUM(B5:B11) | C12: =SUM(C5:C11) | D12: =B12-C12 | E12: =SUM(E5:E11) | F12: =SUM(F5:F11) | G12: =SUM(G5:G11)
A14: Indicadores clave
A15: Costo mensual Azure en COP (pago por uso) | B15: =B12
A16: Costo mensual Azure en COP con reservas a 1 año | B16: =Optimización!$C$14
A17: Costo por enfermera al mes en COP (reservas a 1 año) | B17: =Optimización!$C$14/Supuestos!$B$6
A18: Costo por llamada atendida en COP (reservas a 1 año) | B18: =Optimización!$C$14/Supuestos!$B$8
A19: Costo anual Azure en COP con reservas a 1 año | B19: =Optimización!$C$14*12
A20: Costo total a 3 años (TCO) en COP con reservas a 3 años | B20: =Optimización!$D$14*36
A21: Costo mensual Azure en USD (referencia) | B21: =Azure!$I$54
A22: Diferencia AWS vs Azure (pago por uso) | B22: =(C12-B12)/B12

Sheet Supuestos
A1: Supuestos de carga y dimensionamiento
A2: Valores editables: todas las hojas de costos se recalculan a partir de estas celdas. Precios consultados en Octubre 2026.
A3: Parámetro | B3: Valor | C3: Unidad | D3: Justificación
A4: Horas por mes | B4: 730 | C4: horas | D4: Operación 24/7 (8.760 h / 12 meses)
A5: Días por mes | B5: 30.42 | C5: días | D5: Promedio anual
A6: Enfermeras | B6: 250 | C6: usuarias | D6: Dato del enunciado (250 o más)
A7: Supervisoras y administradores | B7: 20 | C7: usuarios | D7: 1 supervisora cada ~15 enfermeras
A8: Llamadas atendidas por mes | B8: 180000 | C8: llamadas | D8: ~24 llamadas por enfermera por día
A9: Tasa de remisión a centro médico | B9: 0.2 | C9: % | D9: 1 de cada 5 llamadas requiere atención presencial
A10: Remisiones por mes | B10: =B8*B9 | C10: remisiones | D10: Llamadas x tasa de remisión
A11: Peticiones API por llamada | B11: 80 | C11: peticiones | D11: Login, historia, triaje, centros, remisión, refrescos
A12: Peticiones API por mes | B12: =B8*B11 | C12: peticiones | D12: Llamadas x peticiones por llamada
A13: Tokens de entrada por triaje | B13: 2000 | C13: tokens | D13: Síntomas + contexto clínico anonimizado + instrucciones
A14: Tokens de salida por triaje | B14: 500 | C14: tokens | D14: Posibles causas, signos de alarma y recomendación
A15: Peticiones FHIR por llamada | B15: 10 | C15: peticiones | D15: Patient, Condition, Allergy, Medication, Encounter
A16: Almacenamiento clínico FHIR | B16: 200 | C16: GB | D16: Historias clínicas normalizadas
A17: Almacenamiento de documentos (Blob/S3) | B17: 1024 | C17: GB | D17: Adjuntos, reportes, exportaciones
A18: Almacenamiento PostgreSQL aprovisionado | B18: 512 | C18: GB | D18: Casos, remisiones, auditoría y centros
A19: Logs ingeridos por mes | B19: 200 | C19: GB | D19: Aplicación, AKS/EKS, gateway, auditoría
A20: Salida de datos a internet | B20: 500 | C20: GB | D20: Respuestas API y descarga de la SPA
A21: Remisiones con llamada de voz | B21: 0.4 | C21: % | D21: El resto se notifica solo por SMS y correo
A22: Minutos por llamada de voz | B22: 2 | C22: minutos | D22: Aviso breve al centro médico
A23: Muestras Prometheus por mes | B23: 1500 | C23: millones | D23: ~120 series por pod, 30 pods, cada 30 s
A24: Transferencia entre regiones | B24: 300 | C24: GB | D24: Replicación de BD y almacenamiento
... A28: TRM (pesos colombianos por dólar) | B28: 3273.49 | C28: COP | D28: Banco de la República, vigente del 3 al 5 de octubre de 2026

Sheet Azure
A1: Detalle de costos - Azure
A2: Región primaria East US 2, secundaria Central US. Pago por uso (sin descuentos). Precios de lista en USD consultados en Octubre 2026 en la API oficial de precios de Azure.
A3: Categoría | B3: Servicio | C3: Configuración / SKU | D3: Región | E3: Cantidad | F3: Unidad de cobro | G3: Uso mensual | H3: Precio unitario (USD) | I3: Costo mensual (USD) | J3: Costo mensual (COP) | K3: Costo anual (COP) | L3: Referencia
A4: Computación | B4: Azure Kubernetes Service | C4: Plano de control Standard (SLA 99,95%) | D4: East US 2 + Central US | E4: 2 | F4: clúster-hora | G4: =Supuestos!$B$4 | H4: 0.1 | I4: =E4*G4*H4 | J4: =I4*Supuestos!$B$28 | K4: =J4*12 | L4: https://azure.microsoft.com/es-es/pricing/details/kubernetes-service/
A5: Computación | B5: AKS - nodos región primaria | C5: Standard_D4s_v5 Linux (4 vCPU, 16 GB) | D5: East US 2 | E5: =Supuestos!$B$25 | F5: nodo-hora | G5: =Supuestos!$B$4 | H5: 0.192 | I5: =E5*G5*H5 | J5: =I5*Supuestos!$B$28 | K5: =J5*12 | L5: https://azure.microsoft.com/es-es/pricing/details/virtual-machines/linux/
A6: Computación | B6: AKS - nodos región secundaria | C6: Standard_D4s_v5 Linux (4 vCPU, 16 GB) | D6: Central US | E6: =Supuestos!$B$26 | F6: nodo-hora | G6: =Supuestos!$B$4 | H6: 0.192 | I6: =E6*G6*H6 | J6: =I6*Supuestos!$B$28 | K6: =J6*12 | L6: https://azure.microsoft.com/es-es/pricing/details/virtual-machines/linux/
A7: Computación | B7: Discos de SO de los nodos | C7: Premium SSD P10 (128 GB) | D7: Ambas | E7: =Supuestos!$B$25+Supuestos!$B$26 | F7: disco-mes | G7: 1 | H7: 17.92 | I7: =E7*G7*H7 | J7: =I7*Supuestos!$B$28 | K7: =J7*12 | L7: https://azure.microsoft.com/es-es/pricing/details/managed-disks/
A8: Computación | B8: Azure Container Registry | C8: Premium + 1 réplica geográfica | D8: East US 2 + Central US | E8: 2 | F8: registro-día | G8: =Supuestos!$B$5 | H8: 1.6666 | I8: =E8*G8*H8 | J8: =I8*Supuestos!$B$28 | K8: =J8*12 | L8: https://azure.microsoft.com/es-es/pricing/details/container-registry/
A9: Almacenamiento y Bases de Datos | B9: PostgreSQL Flexible Server | C9: General Purpose D4ds v5, 4 vCore, HA zona-redundante (primario + standby) | D9: East US 2 | E9: 2 | F9: servidor-hora | G9: =Supuestos!$B$4 | H9: 0.356 | I9: =E9*G9*H9 | J9: =I9*Supuestos!$B$28 | K9: =J9*12 | L9: https://azure.microsoft.com/es-es/pricing/details/postgresql/flexible-server/
A10: Almacenamiento y Bases de Datos | B10: PostgreSQL - almacenamiento | C10: SSD Premium, se duplica por HA | D10: East US 2 | E10: 2 | F10: GB-mes | G10: =Supuestos!$B$18 | H10: 0.115 | I10: =E10*G10*H10 | J10: =I10*Supuestos!$B$28 | K10: =J10*12 | L10: https://azure.microsoft.com/es-es/pricing/details/postgresql/flexible-server/
A11: Almacenamiento y Bases de Datos | B11: PostgreSQL - réplica geográfica | C11: General Purpose 4 vCore, réplica de lectura | D11: Central US | E11: 1 | F11: servidor-hora | G11: =Supuestos!$B$4 | H11: 0.356 | I11: =E11*G11*H11 | J11: =I11*Supuestos!$B$28 | K11: =J11*12 | L11: https://learn.microsoft.com/azure/postgresql/flexible-server/concepts-read-replicas
A12: Almacenamiento y Bases de Datos | B12: PostgreSQL - almacenamiento réplica | C12: SSD Premium | D12: Central US | E12: 1 | F12: GB-mes | G12: =Supuestos!$B$18 | H12: 0.115 | I12: =E12*G12*H12 | J12: =I12*Supuestos!$B$28 | K12: =J12*12 | L12: https://azure.microsoft.com/es-es/pricing/details/postgresql/flexible-server/
A13: Almacenamiento y Bases de Datos | B13: Azure Cache for Redis | C13: Premium P1 (6 GB, réplica incluida) | D13: East US 2 | E13: 1 | F13: caché-hora | G13: =Supuestos!$B$4 | H13: 0.555 | I13: =E13*G13*H13 | J13: =I13*Supuestos!$B$28 | K13: =J13*12 | L13: https://azure.microsoft.com/es-es/pricing/details/cache/
A14: Almacenamiento y Bases de Datos | B14: Blob Storage | C14: Hot ZRS | D14: East US 2 | E14: 1 | F14: GB-mes | G14: =Supuestos!$B$17 | H14: 0.023 | I14: =E14*G14*H14 | J14: =I14*Supuestos!$B$28 | K14: =J14*12 | L14: https://azure.microsoft.com/es-es/pricing/details/storage/blobs/
A15: Almacenamiento y Bases de Datos | B15: Blob Storage - copia de recuperación | C15: Hot GRS (replicación de objetos) | D15: Central US | E15: 1 | F15: GB-mes | G15: =Supuestos!$B$17 | H15: 0.0368 | I15: =E15*G15*H15 | J15: =I15*Supuestos!$B$28 | K15: =J15*12 | L15: https://azure.microsoft.com/es-es/pricing/details/storage/blobs/
A16: Almacenamiento y Bases de Datos | B16: Health Data Services - FHIR | C16: Almacenamiento estructurado | D16: East US 2 | E16: 1 | F16: GB-mes | G16: =Supuestos!$B$16 | H16: 0.39 | I16: =E16*G16*H16 | J16: =I16*Supuestos!$B$28 | K16: =J16*12 | L16: https://azure.microsoft.com/es-es/pricing/details/health-data-services/
A17: Almacenamiento y Bases de Datos | B17: Health Data Services - FHIR | C17: Peticiones API (50K gratis) | D17: East US 2 | E17: 1 | F17: 100K peticiones | G17: =MAX(0,(Supuestos!$B$8*Supuestos!$B$15-50000)/100000) | H17: 0.54 | I17: =E17*G17*H17 | J17: =I17*Supuestos!$B$28 | K17: =J17*12 | L17: https://azure.microsoft.com/es-es/pricing/details/health-data-services/
A18: Redes | B18: Azure Front Door | C18: Premium - tarifa base (incluye WAF administrado) | D18: Global | E18: 1 | F18: mes | G18: 1 | H18: 330 | I18: =E18*G18*H18 | J18: =I18*Supuestos!$B$28 | K18: =J18*12 | L18: https://azure.microsoft.com/es-es/pricing/details/frontdoor/
A19: Redes | B19: Azure Front Door | C19: Premium - solicitudes | D19: Global | E19: 1 | F19: 10K solicitudes | G19: =Supuestos!$B$12/10000 | H19: 0.015 | I19: =E19*G19*H19 | J19: =I19*Supuestos!$B$28 | K19: =J19*12 | L19: https://azure.microsoft.com/es-es/pricing/details/frontdoor/
A20: Redes | B20: Azure Front Door | C20: Premium - salida de datos (Zona 1) | D20: Global | E20: 1 | F20: GB | G20: =Supuestos!$B$20 | H20: 0.0825 | I20: =E20*G20*H20 | J20: =I20*Supuestos!$B$28 | K20: =J20*12 | L20: https://azure.microsoft.com/es-es/pricing/details/frontdoor/
A21: Redes | B21: API Management | C21: Standard v2 (1 unidad, 50M llamadas incluidas) | D21: East US 2 | E21: 1 | F21: unidad-hora | G21: =Supuestos!$B$4 | H21: 0.9589 | I21: =E21*G21*H21 | J21: =I21*Supuestos!$B$28 | K21: =J21*12 | L21: https://azure.microsoft.com/es-es/pricing/details/api-management/
A22: Redes | B22: API Management | C22: Standard v2 (1 unidad, región pasiva) | D22: Central US | E22: 1 | F22: unidad-hora | G22: =Supuestos!$B$4 | H22: 0.9589 | I22: =E22*G22*H22 | J22: =I22*Supuestos!$B$28 | K22: =J22*12 | L22: https://azure.microsoft.com/es-es/pricing/details/api-management/
A23: Redes | B23: Private Endpoints | C23: PostgreSQL, Redis, Service Bus, Key Vault, Blob, FHIR, OpenAI, ACR, réplicas | D23: Ambas | E23: 10 | F23: endpoint-hora | G23: =Supuestos!$B$4 | H23: 0.01 | I23: =E23*G23*H23 | J23: =I23*Supuestos!$B$28 | K23: =J23*12 | L23: https://azure.microsoft.com/es-es/pricing/details/private-link/
A24: Redes | B24: Private Link - datos procesados | C24: Entrada + salida | D24: Ambas | E24: 1 | F24: GB | G24: 1000 | H24: 0.01 | I24: =E24*G24*H24 | J24: =I24*Supuestos!$B$28 | K24: =J24*12 | L24: https://azure.microsoft.com/es-es/pricing/details/private-link/
A25: Redes | B25: Transferencia entre regiones | C25: Dentro de Norteamérica | D25: Ambas | E25: 1 | F25: GB | G25: =Supuestos!$B$24 | H25: 0.02 | I25: =E25*G25*H25 | J25: =I25*Supuestos!$B$28 | K25: =J25*12 | L25: https://azure.microsoft.com/es-es/pricing/details/bandwidth/
A26: Redes | B26: Azure DNS | C26: 1 zona pública + 10M consultas | D26: Global | E26: 1 | F26: mes | G26: 1 | H26: 4.5 | I26: =E26*G26*H26 | J26: =I26*Supuestos!$B$28 | K26: =J26*12 | L26: https://azure.microsoft.com/es-es/pricing/details/dns/
A27: Seguridad | B27: Microsoft Entra ID | C27: Federación OIDC con el sistema corporativo (licencias existentes de la compañía) | D27: Global | E27: =Supuestos!$B$6+Supuestos!$B$7 | F27: usuario-mes | G27: 1 | H27: 0 | I27: =E27*G27*H27 | J27: =I27*Supuestos!$B$28 | K27: =J27*12 | L27: https://www.microsoft.com/es-es/security/business/microsoft-entra-pricing
A28: Seguridad | B28: Azure Key Vault | C28: Standard, 2 bóvedas (1M operaciones) | D28: Ambas | E28: 1 | F28: 10K operaciones | G28: 100 | H28: 0.03 | I28: =E28*G28*H28 | J28: =I28*Supuestos!$B$28 | K28: =J28*12 | L28: https://azure.microsoft.com/es-es/pricing/details/key-vault/
A29: Seguridad | B29: Defender for Containers | C29: Protección de AKS por vCore | D29: Ambas | E29: =(Supuestos!$B$25+Supuestos!$B$26)*Supuestos!$B$27 | F29: vCore-hora | G29: =Supuestos!$B$4 | H29: 0.00941 | I29: =E29*G29*H29 | J29: =I29*Supuestos!$B$28 | K29: =J29*12 | L29: https://azure.microsoft.com/es-es/pricing/details/defender-for-cloud/
A30: Seguridad | B30: Defender para bases de datos | C30: PostgreSQL (primario + réplica) | D30: Ambas | E30: 2 | F30: servidor-mes | G30: 1 | H30: 15 | I30: =E30*G30*H30 | J30: =I30*Supuestos!$B$28 | K30: =J30*12 | L30: https://azure.microsoft.com/es-es/pricing/details/defender-for-cloud/
A31: Seguridad | B31: Certificados TLS | C31: Administrados por Front Door | D31: Global | E31: 1 | F31: mes | G31: 1 | H31: 0 | I31: =E31*G31*H31 | J31: =I31*Supuestos!$B$28 | K31: =J31*12 | L31: https://learn.microsoft.com/azure/frontdoor/domain
A32: Monitoreo y Logs | B32: Log Analytics + Application Insights | C32: Analytics Logs (5 GB gratis, 31 días de retención) | D32: East US 2 | E32: 1 | F32: GB | G32: =MAX(0,Supuestos!$B$19-5) | H32: 2.76 | I32: =E32*G32*H32 | J32: =I32*Supuestos!$B$28 | K32: =J32*12 | L32: https://azure.microsoft.com/es-es/pricing/details/monitor/
A33: Monitoreo y Logs | B33: Managed Prometheus | C33: Ingesta de métricas | D33: East US 2 | E33: 1 | F33: 10M muestras | G33: =Supuestos!$B$23/10 | H33: 0.16 | I33: =E33*G33*H33 | J33: =I33*Supuestos!$B$28 | K33: =J33*12 | L33: https://azure.microsoft.com/es-es/pricing/details/monitor/
A34: Monitoreo y Logs | B34: Azure Managed Grafana | C34: Standard (instancia) | D34: East US 2 | E34: 1 | F34: hora | G34: =Supuestos!$B$4 | H34: 0.034246 | I34: =E34*G34*H34 | J34: =I34*Supuestos!$B$28 | K34: =J34*12 | L34: https://azure.microsoft.com/es-es/pricing/details/managed-grafana/
A35: Monitoreo y Logs | B35: Azure Managed Grafana | C35: Usuarios activos | D35: East US 2 | E35: 5 | F35: usuario-mes | G35: 1 | H35: 6 | I35: =E35*G35*H35 | J35: =I35*Supuestos!$B$28 | K35: =J35*12 | L35: https://azure.microsoft.com/es-es/pricing/details/managed-grafana/
A36: Monitoreo y Logs | B36: Alertas de logs | C36: Reglas cada 10 minutos | D36: East US 2 | E36: 10 | F36: regla-mes | G36: 1 | H36: 1 | I36: =E36*G36*H36 | J36: =I36*Supuestos!$B$28 | K36: =J36*12 | L36: https://azure.microsoft.com/es-es/pricing/details/monitor/
A37: Monitoreo y Logs | B37: Alertas de métricas | C37: Recursos monitoreados cada 1 minuto | D37: East US 2 | E37: 30 | F37: recurso-mes | G37: 1 | H37: 0.3 | I37: =E37*G37*H37 | J37: =I37*Supuestos!$B$28 | K37: =J37*12 | L37: https://azure.microsoft.com/es-es/pricing/details/monitor/
A38: Servicios de Plataforma | B38: Azure Service Bus | C38: Premium, 1 unidad de mensajería | D38: East US 2 | E38: 1 | F38: MU-hora | G38: =Supuestos!$B$4 | H38: 0.9275 | I38: =E38*G38*H38 | J38: =I38*Supuestos!$B$28 | K38: =J38*12 | L38: https://azure.microsoft.com/es-es/pricing/details/service-bus/
A39: Servicios de Plataforma | B39: Azure OpenAI | C39: gpt-4.1-mini regional - tokens de entrada | D39: East US 2 | E39: 1 | F39: 1M tokens | G39: =Supuestos!$B$8*Supuestos!$B$13/1000000 | H39: 0.44 | I39: =E39*G39*H39 | J39: =I39*Supuestos!$B$28 | K39: =J39*12 | L39: https://azure.microsoft.com/es-es/pricing/details/cognitive-services/openai-service/
A40: Servicios de Plataforma | B40: Azure OpenAI | C40: gpt-4.1-mini regional - tokens de salida | D40: East US 2 | E40: 1 | F40: 1M tokens | G40: =Supuestos!$B$8*Supuestos!$B$14/1000000 | H40: 1.76 | I40: =E40*G40*H40 | J40: =I40*Supuestos!$B$28 | K40: =J40*12 | L40: https://azure.microsoft.com/es-es/pricing/details/cognitive-services/openai-service/
...

Sheet AWS
A1: Detalle de costos - AWS
A2: Región primaria us-east-2 (Ohio), secundaria us-west-2 (Oregón). Pago por uso (sin descuentos). Precios de lista en USD consultados en Octubre 2026 en AWS Price List.
A3: Categoría | B3: Servicio | C3: Configuración / SKU | D3: Región | E3: Cantidad | F3: Unidad de cobro | G3: Uso mensual | H3: Precio unitario (USD) | I3: Costo mensual (USD) | J3: Costo mensual (COP) | K3: Costo anual (COP) | L3: Referencia
A4: Computación | B4: Amazon EKS | C4: Plano de control estándar | D4: us-east-2 + us-west-2 | E4: 2 | F4: clúster-hora | G4: =Supuestos!$B$4 | H4: 0.1 | I4: =E4*G4*H4 | J4: =I4*Supuestos!$B$28 | K4: =J4*12 | L4: https://aws.amazon.com/eks/pricing/
A5: Computación | B5: EKS - nodos región primaria | C5: m6i.xlarge Linux (4 vCPU, 16 GB) | D5: us-east-2 | E5: =Supuestos!$B$25 | F5: nodo-hora | G5: =Supuestos!$B$4 | H5: 0.192 | I5: =E5*G5*H5 | J5: =I5*Supuestos!$B$28 | K5: =J5*12 | L5: https://aws.amazon.com/ec2/pricing/on-demand/
A6: Computación | B6: EKS - nodos región secundaria | C6: m6i.xlarge Linux (4 vCPU, 16 GB) | D6: us-west-2 | E6: =Supuestos!$B$26 | F6: nodo-hora | G6: =Supuestos!$B$4 | H6: 0.192 | I6: =E6*G6*H6 | J6: =I6*Supuestos!$B$28 | K6: =J6*12 | L6: https://aws.amazon.com/ec2/pricing/on-demand/
A7: Computación | B7: EBS de los nodos | C7: gp3 128 GB | D7: Ambas | E7: =(Supuestos!$B$25+Supuestos!$B$26)*128 | F7: GB-mes | G7: 1 | H7: 0.08 | I7: =E7*G7*H7 | J7: =I7*Supuestos!$B$28 | K7: =J7*12 | L7: https://aws.amazon.com/ebs/pricing/
A8: Computación | B8: Amazon ECR | C8: Almacenamiento de imágenes + replicación | D8: Ambas | E8: 2 | F8: GB-mes | G8: 50 | H8: 0.1 | I8: =E8*G8*H8 | J8: =I8*Supuestos!$B$28 | K8: =J8*12 | L8: https://aws.amazon.com/ecr/pricing/
A9: Almacenamiento y Bases de Datos | B9: RDS for PostgreSQL | C9: db.m6i.xlarge Multi-AZ (4 vCPU, 16 GB) | D9: us-east-2 | E9: 1 | F9: instancia-hora | G9: =Supuestos!$B$4 | H9: 0.712 | I9: =E9*G9*H9 | J9: =I9*Supuestos!$B$28 | K9: =J9*12 | L9: https://aws.amazon.com/rds/postgresql/pricing/
A10: Almacenamiento y Bases de Datos | B10: RDS - almacenamiento | C10: gp3 Multi-AZ | D10: us-east-2 | E10: 1 | F10: GB-mes | G10: =Supuestos!$B$18 | H10: 0.23 | I10: =E10*G10*H10 | J10: =I10*Supuestos!$B$28 | K10: =J10*12 | L10: https://aws.amazon.com/rds/postgresql/pricing/
A11: Almacenamiento y Bases de Datos | B11: RDS - réplica entre regiones | C11: db.m6i.xlarge Single-AZ | D11: us-west-2 | E11: 1 | F11: instancia-hora | G11: =Supuestos!$B$4 | H11: 0.356 | I11: =E11*G11*H11 | J11: =I11*Supuestos!$B$28 | K11: =J11*12 | L11: https://aws.amazon.com/rds/postgresql/pricing/
A12: Almacenamiento y Bases de Datos | B12: RDS - almacenamiento réplica | C12: gp3 Single-AZ | D12: us-west-2 | E12: 1 | F12: GB-mes | G12: =Supuestos!$B$18 | H12: 0.115 | I12: =E12*G12*H12 | J12: =I12*Supuestos!$B$28 | K12: =J12*12 | L12: https://aws.amazon.com/rds/postgresql/pricing/
A13: Almacenamiento y Bases de Datos | B13: ElastiCache | C13: cache.m7g.large Valkey, primario + réplica | D13: us-east-2 | E13: 2 | F13: nodo-hora | G13: =Supuestos!$B$4 | H13: 0.1264 | I13: =E13*G13*H13 | J13: =I13*Supuestos!$B$28 | K13: =J13*12 | L13: https://aws.amazon.com/elasticache/pricing/
A14: Almacenamiento y Bases de Datos | B14: Amazon S3 | C14: Standard | D14: us-east-2 | E14: 1 | F14: GB-mes | G14: =Supuestos!$B$17 | H14: 0.023 | I14: =E14*G14*H14 | J14: =I14*Supuestos!$B$28 | K14: =J14*12 | L14: https://aws.amazon.com/s3/pricing/
A15: Almacenamiento y Bases de Datos | B15: Amazon S3 - replicación entre regiones | C15: Standard (copia) | D15: us-west-2 | E15: 1 | F15: GB-mes | G15: =Supuestos!$B$17 | H15: 0.023 | I15: =E15*G15*H15 | J15: =I15*Supuestos!$B$28 | K15: =J15*12 | L15: https://aws.amazon.com/s3/pricing/
A16: Almacenamiento y Bases de Datos | B16: AWS HealthLake | C16: Almacén de datos FHIR R4 | D16: us-east-2 | E16: 1 | F16: hora | G16: =Supuestos!$B$4 | H16: 0.27 | I16: =E16*G16*H16 | J16: =I16*Supuestos!$B$28 | K16: =J16*12 | L16: https://aws.amazon.com/healthlake/pricing/
A17: Almacenamiento y Bases de Datos | B17: AWS HealthLake | C17: Almacenamiento FHIR + índice (10 GB gratis) | D17: us-east-2 | E17: 1 | F17: GB-mes | G17: =MAX(0,Supuestos!$B$16-10) | H17: 0.37 | I17: =E17*G17*H17 | J17: =I17*Supuestos!$B$28 | K17: =J17*12 | L17: https://aws.amazon.com/healthlake/pricing/
A18: Redes | B18: Amazon CloudFront | C18: Salida de datos (primeros 10 TB) | D18: Global | E18: 1 | F18: GB | G18: =Supuestos!$B$20 | H18: 0.085 | I18: =E18*G18*H18 | J18: =I18*Supuestos!$B$28 | K18: =J18*12 | L18: https://aws.amazon.com/cloudfront/pricing/
A19: Redes | B19: Amazon CloudFront | C19: Solicitudes HTTPS | D19: Global | E19: 1 | F19: 10K solicitudes | G19: =Supuestos!$B$12/10000 | H19: 0.01 | I19: =E19*G19*H19 | J19: =I19*Supuestos!$B$28 | K19: =J19*12 | L19: https://aws.amazon.com/cloudfront/pricing/
A20: Redes | B20: Amazon API Gateway | C20: HTTP API | D20: us-east-2 | E20: 1 | F20: 1M solicitudes | G20: =Supuestos!$B$12/1000000 | H20: 1 | I20: =E20*G20*H20 | J20: =I20*Supuestos!$B$28 | K20: =J20*12 | L20: https://aws.amazon.com/api-gateway/pricing/
A21: Redes | B21: Application Load Balancer | C21: 1 por región (hora + LCU estimado) | D21: Ambas | E21: 2 | F21: ALB-hora | G21: =Supuestos!$B$4 | H21: 0.0385 | I21: =E21*G21*H21 | J21: =I21*Supuestos!$B$28 | K21: =J21*12 | L21: https://aws.amazon.com/elasticloadbalancing/pricing/
A22: Redes | B22: NAT Gateway | C22: 1 por región | D22: Ambas | E22: 2 | F22: gateway-hora | G22: =Supuestos!$B$4 | H22: 0.045 | I22: =E22*G22*H22 | J22: =I22*Supuestos!$B$28 | K22: =J22*12 | L22: https://aws.amazon.com/vpc/pricing/
A23: Redes | B23: NAT Gateway - datos procesados | C23: Tráfico saliente de los nodos | D23: Ambas | E23: 1 | F23: GB | G23: 200 | H23: 0.045 | I23: =E23*G23*H23 | J23: =I23*Supuestos!$B$28 | K23: =J23*12 | L23: https://aws.amazon.com/vpc/pricing/
A24: Redes | B24: VPC Interface Endpoints (PrivateLink) | C24: 8 endpoints x 2 zonas | D24: us-east-2 | E24: 16 | F24: endpoint-hora | G24: =Supuestos!$B$4 | H24: 0.01 | I24: =E24*G24*H24 | J24: =I24*Supuestos!$B$28 | K24: =J24*12 | L24: https://aws.amazon.com/privatelink/pricing/
A25: Redes | B25: Transferencia entre regiones | C25: us-east-2 a us-west-2 | D25: Ambas | E25: 1 | F25: GB | G25: =Supuestos!$B$24 | H25: 0.02 | I25: =E25*G25*H25 | J25: =I25*Supuestos!$B$28 | K25: =J25*12 | L25: https://aws.amazon.com/ec2/pricing/on-demand/#Data_Transfer
A26: Redes | B26: Amazon Route 53 | C26: 1 zona, 2 health checks, 10M consultas | D26: Global | E26: 1 | F26: mes | G26: 1 | H26: 6 | I26: =E26*G26*H26 | J26: =I26*Supuestos!$B$28 | K26: =J26*12 | L26: https://aws.amazon.com/route53/pricing/
A27: Seguridad | B27: Amazon Cognito | C27: Usuarios federados OIDC (50 MAU gratis) | D27: us-east-2 | E27: =MAX(0,Supuestos!$B$6+Supuestos!$B$7-50) | F27: MAU | G27: 1 | H27: 0.015 | I27: =E27*G27*H27 | J27: =I27*Supuestos!$B$28 | K27: =J27*12 | L27: https://aws.amazon.com/cognito/pricing/
A28: Seguridad | B28: AWS WAF | C28: 1 Web ACL + 10 reglas | D28: Global | E28: 1 | F28: mes | G28: 1 | H28: 15 | I28: =E28*G28*H28 | J28: =I28*Supuestos!$B$28 | K28: =J28*12 | L28: https://aws.amazon.com/waf/pricing/
A29: Seguridad | B29: AWS WAF | C29: Solicitudes inspeccionadas | D29: Global | E29: 1 | F29: 1M solicitudes | G29: =Supuestos!$B$12/1000000 | H29: 0.6 | I29: =E29*G29*H29 | J29: =I29*Supuestos!$B$28 | K29: =J29*12 | L29: https://aws.amazon.com/waf/pricing/
A30: Seguridad | B30: AWS Secrets Manager + KMS | C30: 20 secretos + 2 llaves | D30: Ambas | E30: 1 | F30: mes | G30: 1 | H30: 10 | I30: =E30*G30*H30 | J30: =I30*Supuestos!$B$28 | K30: =J30*12 | L30: https://aws.amazon.com/secrets-manager/pricing/
A31: Seguridad | B31: Amazon GuardDuty | C31: Protección de EKS en tiempo de ejecución (aprox.) | D31: Ambas | E31: =(Supuestos!$B$25+Supuestos!$B$26)*Supuestos!$B$27 | F31: vCPU-mes | G31: 1 | H31: 1.5 | I31: =E31*G31*H31 | J31: =I31*Supuestos!$B$28 | K31: =J31*12 | L31: https://aws.amazon.com/guardduty/pricing/
A32: Seguridad | B32: AWS Security Hub | C32: Controles de cumplimiento (aprox.) | D32: Ambas | E32: 1 | F32: mes | G32: 1 | H32: 10 | I32: =E32*G32*H32 | J32: =I32*Supuestos!$B$28 | K32: =J32*12 | L32: https://aws.amazon.com/security-hub/pricing/
A33: Seguridad | B33: AWS Certificate Manager | C33: Certificados TLS públicos | D33: Global | E33: 1 | F33: mes | G33: 1 | H33: 0 | I33: =E33*G33*H33 | J33: =I33*Supuestos!$B$28 | K33: =J33*12 | L33: https://aws.amazon.com/certificate-manager/pricing/
A34: Monitoreo y Logs | B34: CloudWatch Logs | C34: Ingesta | D34: us-east-2 | E34: 1 | F34: GB | G34: =Supuestos!$B$19 | H34: 0.5 | I34: =E34*G34*H34 | J34: =I34*Supuestos!$B$28 | K34: =J34*12 | L34: https://aws.amazon.com/cloudwatch/pricing/
A35: Monitoreo y Logs | B35: CloudWatch Logs | C35: Almacenamiento | D35: us-east-2 | E35: 1 | F35: GB-mes | G35: =Supuestos!$B$19 | H35: 0.03 | I35: =E35*G35*H35 | J35: =I35*Supuestos!$B$28 | K35: =J35*12 | L35: https://aws.amazon.com/cloudwatch/pricing/
A36: Monitoreo y Logs | B36: Amazon Managed Service for Prometheus | C36: Ingesta de métricas | D36: us-east-2 | E36: 1 | F36: 10M muestras | G36: =Supuestos!$B$23/10 | H36: 0.9 | I36: =E36*G36*H36 | J36: =I36*Supuestos!$B$28 | K36: =J36*12 | L36: https://aws.amazon.com/prometheus/pricing/
A37: Monitoreo y Logs | B37: Amazon Managed Grafana | C37: 2 editores + 5 visualizadores | D37: us-east-2 | E37: 1 | F37: mes | G37: 1 | H37: 43 | I37: =E37*G37*H37 | J37: =I37*Supuestos!$B$28 | K37: =J37*12 | L37: https://aws.amazon.com/grafana/pricing/
A38: Monitoreo y Logs | B38: CloudWatch Alarms | C38: Alarmas estándar | D38: us-east-2 | E38: 40 | F38: alarma-mes | G38: 1 | H38: 0.1 | I38: =E38*G38*H38 | J38: =I38*Supuestos!$B$28 | K38: =J38*12 | L38: https://aws.amazon.com/cloudwatch/pricing/
A39: Monitoreo y Logs | B39: AWS X-Ray | C39: Trazas (100K gratis) | D39: us-east-2 | E39: 1 | F39: 1M trazas | G39: 5 | H39: 5 | I39: =E39*G39*H39 | J39: =I39*Supuestos!$B$28 | K39: =J39*12 | L39: https://aws.amazon.com/xray/pricing/
A40: Servicios de Plataforma | B40: Amazon SQS + SNS | C40: Mensajería entre microservicios | D40: us-east-2 | E40: 1 | F40: 1M solicitudes | G40: 50 | H40: 0.4 | I40: =E40*G40*H40 | J40: =I40*Supuestos!$B$28 | K40: =J40*12 | L40: https://aws.amazon.com/sqs/pricing/
...

Sheet Optimización
A1: Propuestas de optimización de costos - Azure
A2: Escenarios en pesos colombianos (COP) sobre el costo de pago por uso. Los descuentos de reserva provienen de los precios oficiales de Azure Reservations (East US 2).
A4: Concepto | B4: Pago por uso (COP/mes) | C4: Reservas 1 año (COP/mes) | D4: Reservas 3 años (COP/mes) | E4: Medida aplicada
A5: Nodos AKS (D4s v5) | B5: =(SUMIF(Azure!$B$4:$B$53,"AKS - nodos región primaria",Azure!$J$4:$J$53)+SUMIF(Azure!$B$4:$B$53,"AKS - nodos región secundaria",Azure!$J$4:$J$53)) | C5: =B5*1038/(0.192*8760) | D5: =B5*1993/(0.192*8760*3) | E5: Instancias reservadas por nodo: 1 año = USD 1.038, 3 años = USD 1.993 (vs USD 1.682 por año en pago por uso)
A6: PostgreSQL (primario, standby y réplica) | B6: =(SUMIF(Azure!$B$4:$B$53,"PostgreSQL Flexible Server",Azure!$J$4:$J$53)-SUMIFS(Azure!$J$4:$J$53,Azure!$A$4:$A$53,"Ambiente Dev/Test",Azure!$B$4:$B$53,"PostgreSQL Flexible Server")+SUMIF(Azure!$B$4:$B$53,"PostgreSQL - réplica geográfica",Azure!$J$4:$J$53)) | C6: =B6*468/(0.089*8760) | D6: =B6*936/(0.089*8760*3) | E6: Capacidad reservada por vCore: 1 año = USD 468, 3 años = USD 936 (vs USD 780 por año en pago por uso)
A7: Azure Cache for Redis | B7: =SUMIFS(Azure!$J$4:$J$53,Azure!$A$4:$A$53,"Almacenamiento y Bases de Datos",Azure!$B$4:$B$53,"Azure Cache for Redis") | C7: =B7*(1-0.35) | D7: =B7*(1-0.55) | E7: Reserva de caché Premium (~35% a 1 año, ~55% a 3 años)
A8: Log Analytics | B8: =SUMIFS(Azure!$J$4:$J$53,Azure!$A$4:$A$53,"Monitoreo y Logs",Azure!$B$4:$B$53,"Log Analytics + Application Insights") | C8: =B8*(1-0.40) | D8: =B8*(1-0.40) | E8: Logs de depuración en el plan Basic Logs y muestreo en App Insights (~40%)
A9: Ambiente Dev/Test | B9: =SUMIF(Azure!$A$4:$A$53,"Ambiente Dev/Test",Azure!$J$4:$J$53) | C9: =B9*(1-0.55) | D9: =B9*(1-0.55) | E9: Apagado automático noches y fines de semana + precios Dev/Test
A10: Resto de servicios (sin cambio) | B10: =Azure!$J$54-SUM(B5:B9) | C10: =B10 | D10: =B10 | E10: Servicios de consumo: se optimizan con autoescalado y cuotas
A14: TOTAL MENSUAL | B14: =SUM(B5:B10) | C14: =SUM(C5:C10) | D14: =SUM(D5:D10)
A15: TOTAL ANUAL | B15: =B14*12 | C15: =C14*12 | D15: =D14*12
A16: Ahorro frente a pago por uso | B16: 0 | C16: =1-C14/B14 | D16: =1-D14/B14
A18: Otras medidas recomendadas
A19: • Autoescalado horizontal (HPA) y del clúster: 3 nodos en horario valle y hasta 12 en picos, se paga solo lo usado.
A20: • Azure Savings Plan for Compute como alternativa flexible a las instancias reservadas (hasta ~65% a 3 años).
A21: • Caché de respuestas frecuentes (historias consultadas en la misma llamada, centros por zona) para bajar peticiones FHIR, Maps y OpenAI.
A22: • Políticas de ciclo de vida en Blob Storage: mover documentos de más de 90 días al nivel Cool y de más de 1 año a Archive.
A23: • Presupuestos y alertas de Microsoft Cost Management por grupo de recursos y etiquetas por microservicio.
A24: • Revisar cada trimestre el tamaño de nodos y de la base de datos con Azure Advisor.
A25: • Si la compañía tiene contrato Enterprise Agreement con Microsoft, aplicar los descuentos negociados y Azure Hybrid Benefit.

Sheet Comparación
A1: Comparación de plataformas cloud - Matriz de decisión ponderada
A2: Calificación de 1 (deficiente) a 5 (excelente). El puntaje ponderado define la plataforma elegida.
A4: Criterio | B4: Peso | C4: Azure | D4: AWS | E4: Azure ponderado | F4: AWS ponderado | G4: Justificación
A5: Costo total y opciones de ahorro | B5: 0.2 | C5: 3 | D5: 4 | E5: =B5*C5 | F5: =B5*D5 | G5: AWS es más barato en lista (API Gateway, mensajería y logs). Azure reduce la brecha con reservas y planes de ahorro.
A6: Integración con el sistema de seguridad centralizado | B6: 0.2 | C6: 5 | D6: 4 | E6: =B6*C6 | F6: =B6*D6 | G6: Entra ID se federa de forma nativa vía OIDC/SAML con el directorio corporativo, Acceso Condicional y MFA. En AWS se requiere Cognito como intermediario.
A7: Seguridad y cumplimiento normativo (salud) | B7: 0.2 | C7: 5 | D7: 5 | E7: =B7*C7 | F7: =B7*D7 | G7: Ambos firman BAA de HIPAA y tienen ISO 27001, SOC 2 y HITRUST. Azure suma Defender for Cloud y Purview para datos clínicos.
A8: Servicios de salud e IA | B8: 0.15 | C8: 5 | D8: 4 | E8: =B8*C8 | F8: =B8*D8 | G8: Azure Health Data Services (FHIR) + Azure OpenAI con red privada. AWS ofrece HealthLake y Bedrock, con menos opciones de modelos en red privada regional.
A9: Escalabilidad y alta disponibilidad | B9: 0.1 | C9: 5 | D9: 5 | E9: =B9*C9 | F9: =B9*D9 | G9: Zonas de disponibilidad, Kubernetes administrado y balanceo global en ambos.
A10: Compatibilidad con las tecnologías elegidas | B10: 0.1 | C10: 5 | D10: 4 | E10: =B10*C10 | F10: =B10*D10 | G10: React, Electron, Node.js, Python y GitHub Actions tienen integración de primera clase con Azure (GitHub y Azure son de Microsoft).
A11: Servicios adicionales y ecosistema | B11: 0.05 | C11: 5 | D11: 4 | E11: =B11*C11 | F11: =B11*D11 | G11: Integración con Microsoft 365 y Teams para la comunicación con centros médicos, Power BI para indicadores del call center.
A12: PUNTAJE TOTAL | B12: =SUM(B5:B11) | E12: =SUM(E5:E11) | F12: =SUM(F5:F11) | G12: =IF(E12>F12,"Plataforma elegida: Microsoft Azure","Plataforma elegida: AWS")
A15: Equivalencia de servicios
A16: Necesidad | C16: Azure | E16: AWS | G16: Observación
A17: Identidad federada OIDC | C17: Microsoft Entra ID | E17: Amazon Cognito | G17: Entra ID se conecta directo al directorio corporativo
A18: Entrada global, WAF y failover | C18: Front Door Premium + WAF | E18: CloudFront + WAF + Route 53 | G18: En Azure un solo servicio cubre CDN, WAF y failover
A19: API Gateway | C19: API Management Standard v2 | E19: API Gateway HTTP API | G19: APIM incluye portal de desarrolladores y políticas
A20: Kubernetes administrado | C20: AKS | E20: EKS | G20: Mismo modelo de costo del plano de control
A21: Base de datos relacional | C21: PostgreSQL Flexible Server | E21: RDS for PostgreSQL | G21: Ambos con HA en zonas y réplicas entre regiones
A22: Caché | C22: Azure Cache for Redis | E22: ElastiCache (Valkey)
A23: Repositorio clínico FHIR | C23: Azure Health Data Services | E23: AWS HealthLake | G23: Azure cobra por uso; HealthLake cobra por hora del almacén
A24: Apoyo al diagnóstico | C24: Azure OpenAI (gpt-4.1-mini) | E24: Amazon Bedrock (Nova Pro) | G24: Ambos sin entrenar con datos del cliente
A25: Mapas y rutas | C25: Azure Maps | E25: Amazon Location Service | G25: AWS es más barato por transacción
A26: Notificaciones | C26: Communication Services | E26: End User Messaging + Connect + SES | G26: Azure unifica voz, SMS y correo en un servicio
A27: Mensajería | C27: Service Bus Premium | E27: SQS + SNS | G27: Service Bus Premium da red privada y aislamiento
A28: Monitoreo | C28: Azure Monitor + Grafana | E28: CloudWatch + Managed Grafana

Sheet Referencias
A1: Referencias de precios
A2: Fuentes oficiales consultadas en Octubre 2026. Los precios están sujetos a cambios por parte de cada proveedor.
A3: Fuente | B3: Enlace
A4: Calculadora de precios de Azure | B4: https://azure.microsoft.com/es-es/pricing/calculator/
A5: API oficial de precios minoristas de Azure | B5: https://prices.azure.com/api/retail/prices
A6: Azure Reservations (descuentos por reserva) | B6: https://learn.microsoft.com/azure/cost-management-billing/reservations/save-compute-costs-reservations
A7: Azure Savings Plan for Compute | B7: https://azure.microsoft.com/es-es/pricing/offers/savings-plan-compute/
A8: Calculadora de precios de AWS | B8: https://calculator.aws/
A9: AWS Price List (archivos oficiales de precios) | B9: https://pricing.us-east-1.amazonaws.com/offers/v1.0/aws/index.json
A10: AWS Savings Plans | B10: https://aws.amazon.com/savingsplans/compute-pricing/
A11: Calculadora de precios de Google Cloud | B11: https://cloud.google.com/products/calculator
A12: Cumplimiento HIPAA en Azure | B12: https://learn.microsoft.com/azure/compliance/offerings/offering-hipaa-us
A13: Cumplimiento HIPAA en AWS | B13: https://aws.amazon.com/compliance/hipaa-compliance/
A15: Páginas de precios por servicio
A16: Azure - Azure Kubernetes Service | B16: https://azure.microsoft.com/es-es/pricing/details/kubernetes-service/
A17: Azure - AKS - nodos región primaria | B17: https://azure.microsoft.com/es-es/pricing/details/virtual-machines/linux/
A18: Azure - Discos de SO de los nodos | B18: https://azure.microsoft.com/es-es/pricing/details/managed-disks/
A19: Azure - Azure Container Registry | B19: https://azure.microsoft.com/es-es/pricing/details/container-registry/
A20: Azure - PostgreSQL Flexible Server | B20: https://azure.microsoft.com/es-es/pricing/details/postgresql/flexible-server/
A21: Azure - PostgreSQL - réplica geográfica | B21: https://learn.microsoft.com/azure/postgresql/flexible-server/concepts-read-replicas
A22: Azure - Azure Cache for Redis | B22: https://azure.microsoft.com/es-es/pricing/details/cache/
A23: Azure - Blob Storage | B23: https://azure.microsoft.com/es-es/pricing/details/storage/blobs/
A24: Azure - Health Data Services - FHIR | B24: https://azure.microsoft.com/es-es/pricing/details/health-data-services/
A25: Azure - Azure Front Door | B25: https://azure.microsoft.com/es-es/pricing/details/frontdoor/
A26: Azure - API Management | B26: https://azure.microsoft.com/es-es/pricing/details/api-management/
A27: Azure - Private Endpoints | B27: https://azure.microsoft.com/es-es/pricing/details/private-link/
... A73: AWS - Amazon SES | B73: https://aws.amazon.com/ses/pricing/
